OrderBookSim/OrderBookSim/Outputs/Log1361568987.txt
0--INFO	Added rule
0--INFO	Added rule
0--INFO	Added rule
0--INFO	Added rule
45--INFO	Enqueued order: Price: 0.00, Volume: 769, Type: SELL, Market Order: 1, Participant: 1, Stock:[ID: 0, Symbol: GOOG], Time: 45, OrderNumber: 0
45--INFO	Enqueued order: Price: 2147483647.00, Volume: 891, Type: BUY, Market Order: 1, Participant: 4, Stock:[ID: 0, Symbol: GOOG], Time: 45, OrderNumber: 1
47--INFO	Last Price Set:100.00
47--INFO	Notified Traders of trade47---Trade ID: 0, Price: 100.00, Volume: 769 between ID:[4] and ID:[1]
66--INFO	Enqueued order: Price: 2147483647.00, Volume: 775, Type: BUY, Market Order: 1, Participant: 6, Stock:[ID: 0, Symbol: GOOG], Time: 66, OrderNumber: 2
67--INFO	Enqueued order: Price: 100.00, Volume: 996, Type: BUY, Market Order: 0, Participant: 5, Stock:[ID: 0, Symbol: GOOG], Time: 67, OrderNumber: 3
72--INFO	Enqueued order: Price: 0.00, Volume: 506, Type: SELL, Market Order: 1, Participant: 3, Stock:[ID: 0, Symbol: GOOG], Time: 72, OrderNumber: 4
73--INFO	Last Price Set:100.00
73--INFO	Notified Traders of trade73---Trade ID: 1, Price: 100.00, Volume: 122 between ID:[4] and ID:[3]
73--INFO	Last Price Set:100.00
73--INFO	Notified Traders of trade73---Trade ID: 2, Price: 100.00, Volume: 384 between ID:[6] and ID:[3]
90--INFO	Enqueued order: Price: 0.00, Volume: 365, Type: SELL, Market Order: 1, Participant: 1, Stock:[ID: 0, Symbol: GOOG], Time: 90, OrderNumber: 5
90--INFO	Enqueued order: Price: 2147483647.00, Volume: 362, Type: BUY, Market Order: 1, Participant: 4, Stock:[ID: 0, Symbol: GOOG], Time: 90, OrderNumber: 6
91--INFO	Last Price Set:100.00
91--INFO	Notified Traders of trade91---Trade ID: 3, Price: 100.00, Volume: 365 between ID:[6] and ID:[1]
92--INFO	Enqueued order: Price: 2147483647.00, Volume: 7, Type: BUY, Market Order: 1, Participant: 0, Stock:[ID: 0, Symbol: GOOG], Time: 92, OrderNumber: 7
92--INFO	Enqueued order: Price: 0.00, Volume: 14, Type: SELL, Market Order: 1, Participant: 7, Stock:[ID: 0, Symbol: GOOG], Time: 92, OrderNumber: 8
94--INFO	Last Price Set:100.00
94--INFO	Notified Traders of trade94---Trade ID: 4, Price: 100.00, Volume: 14 between ID:[6] and ID:[7]
110--INFO	Enqueued order: Price: 2147483647.00, Volume: 343, Type: BUY, Market Order: 1, Participant: 2, Stock:[ID: 0, Symbol: GOOG], Time: 110, OrderNumber: 9
132--INFO	Enqueued order: Price: 0.00, Volume: 738, Type: SELL, Market Order: 1, Participant: 6, Stock:[ID: 0, Symbol: GOOG], Time: 132, OrderNumber: 10
133--INFO	Last Price Set:100.00
133--INFO	Notified Traders of trade133---Trade ID: 5, Price: 100.00, Volume: 362 between ID:[4] and ID:[6]
133--INFO	Last Price Set:100.00
133--INFO	Notified Traders of trade133---Trade ID: 6, Price: 100.00, Volume: 7 between ID:[0] and ID:[6]
133--INFO	Last Price Set:100.00
133--INFO	Notified Traders of trade133---Trade ID: 7, Price: 100.00, Volume: 343 between ID:[2] and ID:[6]
133--INFO	Last Price Set:2147483647.00
133--INFO	Notified Traders of trade133---Trade ID: 8, Price: 2147483647.00, Volume: 12 between ID:[6] and ID:[6]
133--INFO	Last Price Set:100.00
133--INFO	Notified Traders of trade133---Trade ID: 9, Price: 100.00, Volume: 14 between ID:[5] and ID:[6]
134--INFO	Enqueued order: Price: 0.00, Volume: 318, Type: SELL, Market Order: 1, Participant: 5, Stock:[ID: 0, Symbol: GOOG], Time: 134, OrderNumber: 11
135--INFO	Enqueued order: Price: 2147483647.00, Volume: 586, Type: BUY, Market Order: 1, Participant: 1, Stock:[ID: 0, Symbol: GOOG], Time: 135, OrderNumber: 12
135--INFO	Enqueued order: Price: 2147483647.00, Volume: 574, Type: BUY, Market Order: 1, Participant: 4, Stock:[ID: 0, Symbol: GOOG], Time: 135, OrderNumber: 13
136--INFO	Last Price Set:100.00
136--INFO	Notified Traders of trade136---Trade ID: 10, Price: 100.00, Volume: 318 between ID:[1] and ID:[5]
144--INFO	Enqueued order: Price: 0.00, Volume: 85, Type: SELL, Market Order: 1, Participant: 3, Stock:[ID: 0, Symbol: GOOG], Time: 144, OrderNumber: 14
145--INFO	Last Price Set:100.00
145--INFO	Notified Traders of trade145---Trade ID: 11, Price: 100.00, Volume: 85 between ID:[1] and ID:[3]
180--INFO	Enqueued order: Price: 2147483647.00, Volume: 830, Type: BUY, Market Order: 1, Participant: 1, Stock:[ID: 0, Symbol: GOOG], Time: 180, OrderNumber: 15
180--INFO	Enqueued order: Price: 2147483647.00, Volume: 142, Type: BUY, Market Order: 1, Participant: 4, Stock:[ID: 0, Symbol: GOOG], Time: 180, OrderNumber: 16
184--INFO	Enqueued order: Price: 0.00, Volume: 80, Type: SELL, Market Order: 1, Participant: 0, Stock:[ID: 0, Symbol: GOOG], Time: 184, OrderNumber: 17
184--INFO	Enqueued order: Price: 0.00, Volume: 418, Type: SELL, Market Order: 1, Participant: 7, Stock:[ID: 0, Symbol: GOOG], Time: 184, OrderNumber: 18
185--INFO	Last Price Set:100.00
185--INFO	Notified Traders of trade185---Trade ID: 12, Price: 100.00, Volume: 80 between ID:[1] and ID:[0]
186--INFO	Last Price Set:100.00
186--INFO	Notified Traders of trade186---Trade ID: 13, Price: 100.00, Volume: 103 between ID:[1] and ID:[7]
186--INFO	Last Price Set:100.00
186--INFO	Notified Traders of trade186---Trade ID: 14, Price: 100.00, Volume: 315 between ID:[4] and ID:[7]
198--INFO	Enqueued order: Price: 2147483647.00, Volume: 201, Type: BUY, Market Order: 1, Participant: 6, Stock:[ID: 0, Symbol: GOOG], Time: 198, OrderNumber: 19
201--INFO	Enqueued order: Price: 99.96, Volume: 840, Type: BUY, Market Order: 0, Participant: 5, Stock:[ID: 0, Symbol: GOOG], Time: 201, OrderNumber: 20
216--INFO	Enqueued order: Price: 99.93, Volume: 657, Type: BUY, Market Order: 0, Participant: 3, Stock:[ID: 0, Symbol: GOOG], Time: 216, OrderNumber: 21
220--INFO	Enqueued order: Price: 2147483647.00, Volume: 891, Type: BUY, Market Order: 1, Participant: 2, Stock:[ID: 0, Symbol: GOOG], Time: 220, OrderNumber: 22
225--INFO	Enqueued order: Price: 0.00, Volume: 620, Type: SELL, Market Order: 1, Participant: 1, Stock:[ID: 0, Symbol: GOOG], Time: 225, OrderNumber: 23
225--INFO	Enqueued order: Price: 2147483647.00, Volume: 791, Type: BUY, Market Order: 1, Participant: 4, Stock:[ID: 0, Symbol: GOOG], Time: 225, OrderNumber: 24
226--INFO	Last Price Set:100.00
226--INFO	Notified Traders of trade226---Trade ID: 15, Price: 100.00, Volume: 259 between ID:[4] and ID:[1]
226--INFO	Last Price Set:100.00
226--INFO	Notified Traders of trade226---Trade ID: 16, Price: 100.00, Volume: 142 between ID:[4] and ID:[1]
226--INFO	Last Price Set:100.00
226--INFO	Notified Traders of trade226---Trade ID: 17, Price: 100.00, Volume: 201 between ID:[6] and ID:[1]
226--INFO	Last Price Set:100.00
226--INFO	Notified Traders of trade226---Trade ID: 18, Price: 100.00, Volume: 18 between ID:[2] and ID:[1]
264--INFO	Enqueued order: Price: 99.96, Volume: 61, Type: BUY, Market Order: 0, Participant: 6, Stock:[ID: 0, Symbol: GOOG], Time: 264, OrderNumber: 25
268--INFO	Enqueued order: Price: 0.00, Volume: 393, Type: SELL, Market Order: 1, Participant: 5, Stock:[ID: 0, Symbol: GOOG], Time: 268, OrderNumber: 26
269--INFO	Last Price Set:100.00
269--INFO	Notified Traders of trade269---Trade ID: 19, Price: 100.00, Volume: 393 between ID:[1] and ID:[5]
270--INFO	Enqueued order: Price: 0.00, Volume: 860, Type: SELL, Market Order: 1, Participant: 1, Stock:[ID: 0, Symbol: GOOG], Time: 270, OrderNumber: 27
270--INFO	Enqueued order: Price: 0.00, Volume: 65, Type: SELL, Market Order: 1, Participant: 4, Stock:[ID: 0, Symbol: GOOG], Time: 270, OrderNumber: 28
271--INFO	Last Price Set:100.00
271--INFO	Notified Traders of trade271---Trade ID: 20, Price: 100.00, Volume: 860 between ID:[2] and ID:[1]
272--INFO	Last Price Set:100.00
272--INFO	Notified Traders of trade272---Trade ID: 21, Price: 100.00, Volume: 65 between ID:[1] and ID:[4]
276--INFO	Enqueued order: Price: 0.00, Volume: 799, Type: SELL, Market Order: 1, Participant: 0, Stock:[ID: 0, Symbol: GOOG], Time: 276, OrderNumber: 29
276--INFO	Enqueued order: Price: 0.00, Volume: 250, Type: SELL, Market Order: 1, Participant: 7, Stock:[ID: 0, Symbol: GOOG], Time: 276, OrderNumber: 30
277--INFO	Last Price Set:100.00
277--INFO	Notified Traders of trade277---Trade ID: 22, Price: 100.00, Volume: 372 between ID:[1] and ID:[0]
