OrderBookSim/OrderBookSim/Outputs/Output1361568987.txt
0,100,0,0,0
1,100,0,0,0
2,100,0,0,0
3,100,0,0,0
4,100,0,0,0
5,100,0,0,0
6,100,0,0,0
7,100,0,0,0
8,100,0,0,0
9,100,0,0,0
10,100,0,0,0
11,100,0,0,0
12,100,0,0,0
13,100,0,0,0
14,100,0,0,0
15,100,0,0,0
16,100,0,0,0
17,100,0,0,0
18,100,0,0,0
19,100,0,0,0
20,100,0,0,0
21,100,0,0,0
22,100,0,0,0
23,100,0,0,0
24,100,0,0,0
25,100,0,0,0
26,100,0,0,0
27,100,0,0,0
28,100,0,0,0
29,100,0,0,0
30,100,0,0,0
31,100,0,0,0
32,100,0,0,0
33,100,0,0,0
34,100,0,0,0
35,100,0,0,0
36,100,0,0,0
37,100,0,0,0
38,100,0,0,0
39,100,0,0,0
40,100,0,0,0
41,100,0,0,0
42,100,0,0,0
43,100,0,0,0
44,100,0,0,0
45,100,0,0,0
46,100,0,1,0
47,100,1,0,1
48,100,1,0,1
49,100,1,0,1
50,100,1,0,1
51,100,1,0,1
52,100,1,0,1
53,100,1,0,1
54,100,1,0,1
55,100,1,0,1
56,100,1,0,1
57,100,1,0,1
58,100,1,0,1
59,100,1,0,1
60,100,1,0,1
61,100,1,0,1
62,100,1,0,1
63,100,1,0,1
64,100,1,0,1
65,100,1,0,1
66,100,1,0,1
67,100,2,0,1
68,100,3,0,1
69,100,3,0,1
70,100,3,0,1
71,100,3,0,1
72,100,3,0,1
73,100,2,0,3
74,100,2,0,3
75,100,2,0,3
76,100,2,0,3
77,100,2,0,3
78,100,2,0,3
79,100,2,0,3
80,100,2,0,3
81,100,2,0,3
82,100,2,0,3
83,100,2,0,3
84,100,2,0,3
85,100,2,0,3
86,100,2,0,3
87,100,2,0,3
88,100,2,0,3
89,100,2,0,3
90,100,2,0,3
91,100,2,0,4
92,100,3,0,4
93,100,4,0,4
94,100,4,0,5
95,100,4,0,5
96,100,4,0,5
97,100,4,0,5
98,100,4,0,5
99,100,4,0,5
100,100,4,0,5
101,100,4,0,5
102,100,4,0,5
103,100,4,0,5
104,100,4,0,5
105,100,4,0,5
106,100,4,0,5
107,100,4,0,5
108,100,4,0,5
109,100,4,0,5
110,100,4,0,5
111,100,5,0,5
112,100,5,0,5
113,100,5,0,5
114,100,5,0,5
115,100,5,0,5
116,100,5,0,5
117,100,5,0,5
118,100,5,0,5
119,100,5,0,5
120,100,5,0,5
121,100,5,0,5
122,100,5,0,5
123,100,5,0,5
124,100,5,0,5
125,100,5,0,5
126,100,5,0,5
127,100,5,0,5
128,100,5,0,5
129,100,5,0,5
130,100,5,0,5
131,100,5,0,5
132,100,5,0,5
133,100,1,0,10
134,100,1,0,10
135,100,1,1,10
136,100,2,0,11
137,100,3,0,11
138,100,3,0,11
139,100,3,0,11
140,100,3,0,11
141,100,3,0,11
142,100,3,0,11
143,100,3,0,11
144,100,3,0,11
145,100,3,0,12
146,100,3,0,12
147,100,3,0,12
148,100,3,0,12
149,100,3,0,12
150,100,3,0,12
151,100,3,0,12
152,100,3,0,12
153,100,3,0,12
154,100,3,0,12
155,100,3,0,12
156,100,3,0,12
157,100,3,0,12
158,100,3,0,12
159,100,3,0,12
160,100,3,0,12
161,100,3,0,12
162,100,3,0,12
163,100,3,0,12
164,100,3,0,12
165,100,3,0,12
166,100,3,0,12
167,100,3,0,12
168,100,3,0,12
169,100,3,0,12
170,100,3,0,12
171,100,3,0,12
172,100,3,0,12
173,100,3,0,12
174,100,3,0,12
175,100,3,0,12
176,100,3,0,12
177,100,3,0,12
178,100,3,0,12
179,100,3,0,12
180,100,3,0,12
181,100,4,0,12
182,100,5,0,12
183,100,5,0,12
184,100,5,0,12
185,100,5,0,13
186,100,4,0,15
187,100,4,0,15
188,100,4,0,15
189,100,4,0,15
190,100,4,0,15
191,100,4,0,15
192,100,4,0,15
193,100,4,0,15
194,100,4,0,15
195,100,4,0,15
196,100,4,0,15
197,100,4,0,15
198,100,4,0,15
199,100,5,0,15
200,100,5,0,15
201,100,5,0,15
202,100,6,0,15
203,100,6,0,15
204,100,6,0,15
205,100,6,0,15
206,100,6,0,15
207,100,6,0,15
208,100,6,0,15
209,100,6,0,15
210,100,6,0,15
211,100,6,0,15
212,100,6,0,15
213,100,6,0,15
214,100,6,0,15
215,100,6,0,15
216,100,6,0,15
217,100,7,0,15
218,100,7,0,15
219,100,7,0,15
220,100,7,0,15
221,100,8,0,15
222,100,8,0,15
223,100,8,0,15
224,100,8,0,15
225,100,8,0,15
226,100,5,0,19
227,100,6,0,19
228,100,6,0,19
229,100,6,0,19
230,100,6,0,19
231,100,6,0,19
232,100,6,0,19
233,100,6,0,19
234,100,6,0,19
235,100,6,0,19
236,100,6,0,19
237,100,6,0,19
238,100,6,0,19
239,100,6,0,19
240,100,6,0,19
241,100,6,0,19
242,100,6,0,19
243,100,6,0,19
244,100,6,0,19
245,100,6,0,19
246,100,6,0,19
247,100,6,0,19
248,100,6,0,19
249,100,6,0,19
250,100,6,0,19
251,100,6,0,19
252,100,6,0,19
253,100,6,0,19
254,100,6,0,19
255,100,6,0,19
256,100,6,0,19
257,100,6,0,19
258,100,6,0,19
259,100,6,0,19
260,100,6,0,19
261,100,6,0,19
262,100,6,0,19
263,100,6,0,19
264,100,6,0,19
265,100,7,0,19
266,100,7,0,19
267,100,7,0,19
268,100,7,0,19
269,100,7,0,20
270,100,7,0,20
271,100,7,0,21
272,100,7,0,22
273,100,7,0,22
274,100,7,0,22
275,100,7,0,22
276,100,7,0,22
277,100,5,0,25
278,100,5,0,26
279,100,5,0,26
280,100,5,0,26
281,100,5,0,26
282,100,5,0,26
283,100,5,0,26
284,100,5,0,26
285,100,5,0,26
286,100,5,0,26
287,100,5,0,26
288,100,5,0,26
289,100,4,0,28
290,100,4,0,28
291,100,4,0,28
292,100,4,0,28
293,100,4,0,28
294,100,4,0,28
295,100,4,0,28
296,100,4,0,28
297,100,4,0,28
298,100,4,0,28
299,100,4,0,28
300,100,4,0,28
301,100,4,0,28
302,100,4,0,28
303,100,4,0,28
304,100,4,0,28
305,100,4,0,28
306,100,4,0,28
307,100,4,0,28
308,100,4,0,28
309,100,4,0,28
310,100,4,0,28
311,100,4,0,28
312,100,4,0,28
313,100,4,0,28
314,100,4,0,28
315,100,4,0,28
316,100,5,0,28
317,100,6,0,28
318,100,6,0,28
319,100,6,0,28
320,100,6,0,28
321,100,6,0,28
322,100,6,0,28
323,100,6,0,28
324,100,6,0,28
325,100,6,0,28
326,100,6,0,28
327,100,6,0,28
328,100,6,0,28
329,100,6,0,28
330,100,6,0,28
331,100,7,0,28
332,100,8,0,28
333,100,8,0,28
334,100,8,0,28
335,100,8,0,28
336,100,8,0,29
337,100,8,0,29
338,100,8,0,29
339,100,8,0,29
340,100,8,0,29
341,100,8,0,29
342,100,8,0,29
343,100,8,0,29
344,100,8,0,29
345,100,8,0,29
346,100,8,0,29
347,100,8,0,29
348,100,8,0,29
349,100,8,0,29
350,100,8,0,29
351,100,8,0,29
352,100,8,0,29
353,100,8,0,29
354,100,8,0,29
355,100,8,0,29
356,100,8,0,29
357,100,8,0,29
358,100,8,0,29
359,100,8,0,29
360,100,8,0,29
361,100,9,0,29
362,100,10,0,29
363,100.08,9,0,31
364,100.08,9,0,31
365,100.08,9,0,31
366,100.08,9,0,31
367,100.08,9,0,31
368,100.08,9,0,31
369,100.08,8,0,33
370,100.08,9,0,33
371,100.08,9,0,33
372,100.08,9,0,33
373,100.08,9,0,33
374,100.08,9,0,33
375,100.08,9,0,33
376,100.08,9,0,33
377,100.08,9,0,33
378,100.08,9,0,33
379,100.08,9,0,33
380,100.08,9,0,33
381,100.08,9,0,33
382,100.08,9,0,33
383,100.08,9,0,33
384,100.08,9,0,33
385,100.08,9,0,33
386,100.08,9,0,33
387,100.08,9,0,33
388,100.08,9,0,33
389,100.08,9,0,33
390,100.08,9,0,33
391,100.08,9,0,33
392,100.08,9,0,33
393,100.08,9,0,33
394,100.08,9,0,33
395,100.08,9,0,33
396,100.08,9,0,33
397,100.08,10,0,33
398,100.08,10,0,33
399,100.08,10,0,33
400,100.08,10,0,33
401,100.08,10,0,33
402,100.08,10,0,33
403,100.08,11,0,33
404,100.08,11,0,33
405,100.08,11,0,33
406,100.08,12,0,33
407,100.08,11,0,35
408,100.08,11,0,35
409,100.08,11,0,35
410,100.08,11,0,35
411,100.08,11,0,35
412,100.08,11,0,35
413,100.08,11,0,35
414,100.08,11,0,35
415,100.08,11,0,35
416,100.08,11,0,35
417,100.08,11,0,35
418,100.08,11,0,35
419,100.08,11,0,35
420,100.08,11,0,35
421,100.08,11,0,35
422,100.08,11,0,35
423,100.08,11,0,35
424,100.08,11,0,35
425,100.08,11,0,35
426,100.08,11,0,35
427,100.08,11,0,35
428,100.08,11,0,35
429,100.08,11,0,35
430,100.08,11,0,35
431,100.08,11,0,35
432,100.08,11,0,35
433,100.08,10,0,37
434,100.08,10,0,37
435,100.08,10,0,37
436,100.08,10,0,37
437,100.08,10,0,37
438,100.08,10,0,37
439,100.08,10,0,37
440,100.08,10,0,37
441,100.08,11,0,37
442,100.08,11,0,37
443,100.08,11,0,37
444,100.08,11,0,37
445,100.08,11,0,37
446,100.08,11,0,37
447,100.08,11,0,37
448,100.08,11,0,37
449,100.08,11,0,37
450,100.08,11,0,37
451,100.08,12,0,37
452,100.08,13,0,37
453,100.08,13,0,37
454,100.08,13,0,37
455,100.08,13,0,37
456,100.08,13,0,37
457,100.08,13,0,37
458,100.08,13,0,37
459,100.08,13,0,37
460,100.08,13,0,37
461,100.08,14,0,37
462,100.08,12,0,40
463,100.08,13,0,40
464,100.08,13,0,40
465,100.08,13,0,40
466,100.08,13,0,40
467,100.08,13,0,40
468,100.08,13,0,40
469,100.08,13,0,40
470,100.08,13,0,41
471,100.08,13,0,41
472,100.08,13,0,41
473,100.08,13,0,41
474,100.08,13,0,41
475,100.08,13,0,41
476,100.08,13,0,41
477,100.08,13,0,41
478,100.08,13,0,41
479,100.08,13,0,41
480,100.08,13,0,41
481,100.08,13,0,41
482,100.08,13,0,41
483,100.08,13,0,41
484,100.08,13,0,41
485,100.08,13,0,41
486,100.08,13,0,41
487,100.08,13,0,41
488,100.08,13,0,41
489,100.08,13,0,41
490,100.08,13,0,41
491,100.08,13,0,41
492,100.08,13,0,41
493,100.08,13,0,41
494,100.08,13,0,41
495,100.08,13,0,41
496,100.08,14,0,41
497,100.08,13,0,43
498,100.08,13,0,43
499,100.08,13,0,43
500,100.08,13,0,43
501,100.08,13,0,43
502,100.08,13,0,43
503,100.08,13,0,43
504,100.08,13,0,43
505,100.11,13,0,44
506,100.11,13,0,44
507,100.11,13,0,44
508,100.11,13,0,44
509,100.11,13,0,44
510,100.11,13,0,44
511,100.11,13,0,44
512,100.11,13,0,44
